===== 2025-10-11T11:57:28-05:00 â€” last 1000 lines =====
        hass,
        ^^^^^
    ...<8 lines>...
        True,
        ^^^^^
    ),
    ^
  File "/usr/src/homeassistant/homeassistant/components/recorder/history/__init__.py", line 104, in get_significant_states
    return _target(
        hass,
    ...<8 lines>...
        compressed_state_format,
    )
  File "/usr/src/homeassistant/homeassistant/components/recorder/history/modern.py", line 129, in get_significant_states
    return get_significant_states_with_session(
        hass,
    ...<9 lines>...
        compressed_state_format,
    )
  File "/usr/src/homeassistant/homeassistant/components/recorder/history/modern.py", line 293, in get_significant_states_with_session
    execute_stmt_lambda_element(session, stmt, None, end_time, orm_rows=False),
    ~~~~~~~~~~~~~~~~~~~~~~~~~~~^^^^^^^^^^^^^^^^^^^^^^^^^^^^^^^^^^^^^^^^^^^^^^^
  File "/usr/src/homeassistant/homeassistant/components/recorder/util.py", line 190, in execute_stmt_lambda_element
    executed = session.connection().execute(stmt)
  File "/usr/local/lib/python3.13/site-packages/sqlalchemy/engine/base.py", line 1415, in execute
    return meth(
        self,
        distilled_parameters,
        execution_options or NO_OPTIONS,
    )
  File "/usr/local/lib/python3.13/site-packages/sqlalchemy/sql/lambdas.py", line 594, in _execute_on_connection
    return connection._execute_clauseelement(
           ~~~~~~~~~~~~~~~~~~~~~~~~~~~~~~~~~^
        self, distilled_params, execution_options
        ^^^^^^^^^^^^^^^^^^^^^^^^^^^^^^^^^^^^^^^^^
    )
    ^
  File "/usr/local/lib/python3.13/site-packages/sqlalchemy/engine/base.py", line 1637, in _execute_clauseelement
    ret = self._execute_context(
        dialect,
    ...<8 lines>...
        cache_hit=cache_hit,
    )
  File "/usr/local/lib/python3.13/site-packages/sqlalchemy/engine/base.py", line 1842, in _execute_context
    return self._exec_single_context(
           ~~~~~~~~~~~~~~~~~~~~~~~~~^
        dialect, context, statement, parameters
        ^^^^^^^^^^^^^^^^^^^^^^^^^^^^^^^^^^^^^^^
    )
    ^
  File "/usr/local/lib/python3.13/site-packages/sqlalchemy/engine/base.py", line 1982, in _exec_single_context
    self._handle_dbapi_exception(
    ~~~~~~~~~~~~~~~~~~~~~~~~~~~~^
        e, str_statement, effective_parameters, cursor, context
        ^^^^^^^^^^^^^^^^^^^^^^^^^^^^^^^^^^^^^^^^^^^^^^^^^^^^^^^
    )
    ^
  File "/usr/local/lib/python3.13/site-packages/sqlalchemy/engine/base.py", line 2351, in _handle_dbapi_exception
    raise sqlalchemy_exception.with_traceback(exc_info[2]) from e
  File "/usr/local/lib/python3.13/site-packages/sqlalchemy/engine/base.py", line 1963, in _exec_single_context
    self.dialect.do_execute(
    ~~~~~~~~~~~~~~~~~~~~~~~^
        cursor, str_statement, effective_parameters, context
        ^^^^^^^^^^^^^^^^^^^^^^^^^^^^^^^^^^^^^^^^^^^^^^^^^^^^
    )
    ^
  File "/usr/local/lib/python3.13/site-packages/sqlalchemy/engine/default.py", line 943, in do_execute
    cursor.execute(statement, parameters)
    ~~~~~~~~~~~~~~^^^^^^^^^^^^^^^^^^^^^^^
sqlalchemy.exc.OperationalError: (sqlite3.OperationalError) no such table: states
[SQL: SELECT states.metadata_id, states.state, states.last_updated_ts 
FROM states 
WHERE (states.last_changed_ts = states.last_updated_ts OR states.last_changed_ts IS NULL) AND states.metadata_id IN (?) AND states.last_updated_ts > ? AND states.last_updated_ts < ? ORDER BY states.metadata_id, states.last_updated_ts]
[parameters: (45, 1760186486.138183, 1760201024.693016)]
(Background on this error at: https://sqlalche.me/e/20/e3q8)
2025-10-11 11:44:54.398 ERROR (DbWorker_3) [homeassistant.components.recorder.util] Error executing query: (sqlite3.OperationalError) no such table: statistics_meta
[SQL: SELECT statistics_meta.id, statistics_meta.statistic_id, statistics_meta.source, statistics_meta.unit_of_measurement, statistics_meta.has_sum, statistics_meta.name, statistics_meta.mean_type 
FROM statistics_meta 
WHERE statistics_meta.statistic_id IN (?)]
[parameters: ('sun.sun',)]
(Background on this error at: https://sqlalche.me/e/20/e3q8)
2025-10-11 11:44:54.420 ERROR (DbWorker_2) [homeassistant.components.recorder.util] Error executing query: (sqlite3.OperationalError) no such table: states
[SQL: SELECT states.metadata_id, states.state, states.last_updated_ts 
FROM states 
WHERE (states.last_changed_ts = states.last_updated_ts OR states.last_changed_ts IS NULL) AND states.metadata_id IN (?) AND states.last_updated_ts > ? AND states.last_updated_ts < ? ORDER BY states.metadata_id, states.last_updated_ts]
[parameters: (45, 1760186486.138183, 1760201094.3874)]
(Background on this error at: https://sqlalche.me/e/20/e3q8)
2025-10-11 11:44:54.500 ERROR (DbWorker_3) [homeassistant.components.recorder.util] Error executing query: (sqlite3.OperationalError) no such table: statistics_meta
[SQL: SELECT statistics_meta.id, statistics_meta.statistic_id, statistics_meta.source, statistics_meta.unit_of_measurement, statistics_meta.has_sum, statistics_meta.name, statistics_meta.mean_type 
FROM statistics_meta 
WHERE statistics_meta.statistic_id IN (?)]
[parameters: ('sun.sun',)]
(Background on this error at: https://sqlalche.me/e/20/e3q8)
2025-10-11 11:44:54.523 ERROR (DbWorker_2) [homeassistant.components.recorder.util] Error executing query: (sqlite3.OperationalError) no such table: states
[SQL: SELECT states.metadata_id, states.state, states.last_updated_ts 
FROM states 
WHERE (states.last_changed_ts = states.last_updated_ts OR states.last_changed_ts IS NULL) AND states.metadata_id IN (?) AND states.last_updated_ts > ? AND states.last_updated_ts < ? ORDER BY states.metadata_id, states.last_updated_ts]
[parameters: (45, 1760186486.138183, 1760201094.3874)]
(Background on this error at: https://sqlalche.me/e/20/e3q8)
2025-10-11 11:44:54.602 ERROR (DbWorker_3) [homeassistant.components.recorder.util] Error executing query: (sqlite3.OperationalError) no such table: statistics_meta
[SQL: SELECT statistics_meta.id, statistics_meta.statistic_id, statistics_meta.source, statistics_meta.unit_of_measurement, statistics_meta.has_sum, statistics_meta.name, statistics_meta.mean_type 
FROM statistics_meta 
WHERE statistics_meta.statistic_id IN (?)]
[parameters: ('sun.sun',)]
(Background on this error at: https://sqlalche.me/e/20/e3q8)
2025-10-11 11:44:54.603 ERROR (DbWorker_3) [homeassistant.helpers.recorder] Error executing query
Traceback (most recent call last):
  File "/usr/local/lib/python3.13/site-packages/sqlalchemy/engine/base.py", line 1963, in _exec_single_context
    self.dialect.do_execute(
    ~~~~~~~~~~~~~~~~~~~~~~~^
        cursor, str_statement, effective_parameters, context
        ^^^^^^^^^^^^^^^^^^^^^^^^^^^^^^^^^^^^^^^^^^^^^^^^^^^^
    )
    ^
  File "/usr/local/lib/python3.13/site-packages/sqlalchemy/engine/default.py", line 943, in do_execute
    cursor.execute(statement, parameters)
    ~~~~~~~~~~~~~~^^^^^^^^^^^^^^^^^^^^^^^
sqlite3.OperationalError: no such table: statistics_meta

The above exception was the direct cause of the following exception:

Traceback (most recent call last):
  File "/usr/src/homeassistant/homeassistant/helpers/recorder.py", line 95, in session_scope
    yield session
  File "/usr/src/homeassistant/homeassistant/components/recorder/statistics.py", line 1989, in statistics_during_period
    return _statistics_during_period_with_session(
        hass,
    ...<6 lines>...
        types,
    )
  File "/usr/src/homeassistant/homeassistant/components/recorder/statistics.py", line 1879, in _statistics_during_period_with_session
    metadata = get_instance(hass).statistics_meta_manager.get_many(
        session, statistic_ids=statistic_ids
    )
  File "/usr/src/homeassistant/homeassistant/components/recorder/table_managers/statistics_meta.py", line 282, in get_many
    return results | self._get_from_database(
                     ~~~~~~~~~~~~~~~~~~~~~~~^
        session, statistic_ids=missing_statistic_id
        ^^^^^^^^^^^^^^^^^^^^^^^^^^^^^^^^^^^^^^^^^^^
    )
    ^
  File "/usr/src/homeassistant/homeassistant/components/recorder/table_managers/statistics_meta.py", line 115, in _get_from_database
    for row in execute_stmt_lambda_element(
               ~~~~~~~~~~~~~~~~~~~~~~~~~~~^
        session,
        ^^^^^^^^
    ...<6 lines>...
        orm_rows=False,
        ^^^^^^^^^^^^^^^
    ):
    ^
  File "/usr/src/homeassistant/homeassistant/components/recorder/util.py", line 190, in execute_stmt_lambda_element
    executed = session.connection().execute(stmt)
  File "/usr/local/lib/python3.13/site-packages/sqlalchemy/engine/base.py", line 1415, in execute
    return meth(
        self,
        distilled_parameters,
        execution_options or NO_OPTIONS,
    )
  File "/usr/local/lib/python3.13/site-packages/sqlalchemy/sql/lambdas.py", line 594, in _execute_on_connection
    return connection._execute_clauseelement(
           ~~~~~~~~~~~~~~~~~~~~~~~~~~~~~~~~~^
        self, distilled_params, execution_options
        ^^^^^^^^^^^^^^^^^^^^^^^^^^^^^^^^^^^^^^^^^
    )
    ^
  File "/usr/local/lib/python3.13/site-packages/sqlalchemy/engine/base.py", line 1637, in _execute_clauseelement
    ret = self._execute_context(
        dialect,
    ...<8 lines>...
        cache_hit=cache_hit,
    )
  File "/usr/local/lib/python3.13/site-packages/sqlalchemy/engine/base.py", line 1842, in _execute_context
    return self._exec_single_context(
           ~~~~~~~~~~~~~~~~~~~~~~~~~^
        dialect, context, statement, parameters
        ^^^^^^^^^^^^^^^^^^^^^^^^^^^^^^^^^^^^^^^
    )
    ^
  File "/usr/local/lib/python3.13/site-packages/sqlalchemy/engine/base.py", line 1982, in _exec_single_context
    self._handle_dbapi_exception(
    ~~~~~~~~~~~~~~~~~~~~~~~~~~~~^
        e, str_statement, effective_parameters, cursor, context
        ^^^^^^^^^^^^^^^^^^^^^^^^^^^^^^^^^^^^^^^^^^^^^^^^^^^^^^^
    )
    ^
  File "/usr/local/lib/python3.13/site-packages/sqlalchemy/engine/base.py", line 2351, in _handle_dbapi_exception
    raise sqlalchemy_exception.with_traceback(exc_info[2]) from e
  File "/usr/local/lib/python3.13/site-packages/sqlalchemy/engine/base.py", line 1963, in _exec_single_context
    self.dialect.do_execute(
    ~~~~~~~~~~~~~~~~~~~~~~~^
        cursor, str_statement, effective_parameters, context
        ^^^^^^^^^^^^^^^^^^^^^^^^^^^^^^^^^^^^^^^^^^^^^^^^^^^^
    )
    ^
  File "/usr/local/lib/python3.13/site-packages/sqlalchemy/engine/default.py", line 943, in do_execute
    cursor.execute(statement, parameters)
    ~~~~~~~~~~~~~~^^^^^^^^^^^^^^^^^^^^^^^
sqlalchemy.exc.OperationalError: (sqlite3.OperationalError) no such table: statistics_meta
[SQL: SELECT statistics_meta.id, statistics_meta.statistic_id, statistics_meta.source, statistics_meta.unit_of_measurement, statistics_meta.has_sum, statistics_meta.name, statistics_meta.mean_type 
FROM statistics_meta 
WHERE statistics_meta.statistic_id IN (?)]
[parameters: ('sun.sun',)]
(Background on this error at: https://sqlalche.me/e/20/e3q8)
2025-10-11 11:44:54.628 ERROR (DbWorker_2) [homeassistant.components.recorder.util] Error executing query: (sqlite3.OperationalError) no such table: states
[SQL: SELECT states.metadata_id, states.state, states.last_updated_ts 
FROM states 
WHERE (states.last_changed_ts = states.last_updated_ts OR states.last_changed_ts IS NULL) AND states.metadata_id IN (?) AND states.last_updated_ts > ? AND states.last_updated_ts < ? ORDER BY states.metadata_id, states.last_updated_ts]
[parameters: (45, 1760186486.138183, 1760201094.3874)]
(Background on this error at: https://sqlalche.me/e/20/e3q8)
2025-10-11 11:44:54.628 ERROR (DbWorker_2) [homeassistant.helpers.recorder] Error executing query
Traceback (most recent call last):
  File "/usr/local/lib/python3.13/site-packages/sqlalchemy/engine/base.py", line 1963, in _exec_single_context
    self.dialect.do_execute(
    ~~~~~~~~~~~~~~~~~~~~~~~^
        cursor, str_statement, effective_parameters, context
        ^^^^^^^^^^^^^^^^^^^^^^^^^^^^^^^^^^^^^^^^^^^^^^^^^^^^
    )
    ^
  File "/usr/local/lib/python3.13/site-packages/sqlalchemy/engine/default.py", line 943, in do_execute
    cursor.execute(statement, parameters)
    ~~~~~~~~~~~~~~^^^^^^^^^^^^^^^^^^^^^^^
sqlite3.OperationalError: no such table: states

The above exception was the direct cause of the following exception:

Traceback (most recent call last):
  File "/usr/src/homeassistant/homeassistant/helpers/recorder.py", line 95, in session_scope
    yield session
  File "/usr/src/homeassistant/homeassistant/components/recorder/history/modern.py", line 129, in get_significant_states
    return get_significant_states_with_session(
        hass,
    ...<9 lines>...
        compressed_state_format,
    )
  File "/usr/src/homeassistant/homeassistant/components/recorder/history/modern.py", line 293, in get_significant_states_with_session
    execute_stmt_lambda_element(session, stmt, None, end_time, orm_rows=False),
    ~~~~~~~~~~~~~~~~~~~~~~~~~~~^^^^^^^^^^^^^^^^^^^^^^^^^^^^^^^^^^^^^^^^^^^^^^^
  File "/usr/src/homeassistant/homeassistant/components/recorder/util.py", line 190, in execute_stmt_lambda_element
    executed = session.connection().execute(stmt)
  File "/usr/local/lib/python3.13/site-packages/sqlalchemy/engine/base.py", line 1415, in execute
    return meth(
        self,
        distilled_parameters,
        execution_options or NO_OPTIONS,
    )
  File "/usr/local/lib/python3.13/site-packages/sqlalchemy/sql/lambdas.py", line 594, in _execute_on_connection
    return connection._execute_clauseelement(
           ~~~~~~~~~~~~~~~~~~~~~~~~~~~~~~~~~^
        self, distilled_params, execution_options
        ^^^^^^^^^^^^^^^^^^^^^^^^^^^^^^^^^^^^^^^^^
    )
    ^
  File "/usr/local/lib/python3.13/site-packages/sqlalchemy/engine/base.py", line 1637, in _execute_clauseelement
    ret = self._execute_context(
        dialect,
    ...<8 lines>...
        cache_hit=cache_hit,
    )
  File "/usr/local/lib/python3.13/site-packages/sqlalchemy/engine/base.py", line 1842, in _execute_context
    return self._exec_single_context(
           ~~~~~~~~~~~~~~~~~~~~~~~~~^
        dialect, context, statement, parameters
        ^^^^^^^^^^^^^^^^^^^^^^^^^^^^^^^^^^^^^^^
    )
    ^
  File "/usr/local/lib/python3.13/site-packages/sqlalchemy/engine/base.py", line 1982, in _exec_single_context
    self._handle_dbapi_exception(
    ~~~~~~~~~~~~~~~~~~~~~~~~~~~~^
        e, str_statement, effective_parameters, cursor, context
        ^^^^^^^^^^^^^^^^^^^^^^^^^^^^^^^^^^^^^^^^^^^^^^^^^^^^^^^
    )
    ^
  File "/usr/local/lib/python3.13/site-packages/sqlalchemy/engine/base.py", line 2351, in _handle_dbapi_exception
    raise sqlalchemy_exception.with_traceback(exc_info[2]) from e
  File "/usr/local/lib/python3.13/site-packages/sqlalchemy/engine/base.py", line 1963, in _exec_single_context
    self.dialect.do_execute(
    ~~~~~~~~~~~~~~~~~~~~~~~^
        cursor, str_statement, effective_parameters, context
        ^^^^^^^^^^^^^^^^^^^^^^^^^^^^^^^^^^^^^^^^^^^^^^^^^^^^
    )
    ^
  File "/usr/local/lib/python3.13/site-packages/sqlalchemy/engine/default.py", line 943, in do_execute
    cursor.execute(statement, parameters)
    ~~~~~~~~~~~~~~^^^^^^^^^^^^^^^^^^^^^^^
sqlalchemy.exc.OperationalError: (sqlite3.OperationalError) no such table: states
[SQL: SELECT states.metadata_id, states.state, states.last_updated_ts 
FROM states 
WHERE (states.last_changed_ts = states.last_updated_ts OR states.last_changed_ts IS NULL) AND states.metadata_id IN (?) AND states.last_updated_ts > ? AND states.last_updated_ts < ? ORDER BY states.metadata_id, states.last_updated_ts]
[parameters: (45, 1760186486.138183, 1760201094.3874)]
(Background on this error at: https://sqlalche.me/e/20/e3q8)
2025-10-11 11:44:54.621 ERROR (MainThread) [homeassistant.components.websocket_api.http.connection] [281471705842048] Error handling message: Unknown error (unknown_error) Blake Foster from 192.168.1.65 (Mozilla/5.0 (iPhone; CPU iPhone OS 18_7 like Mac OS X) AppleWebKit/605.1.15 (KHTML, like Gecko) Home Assistant/2025.9.3 (io.robbie.HomeAssistant; build:2025.1423; iOS 26.0.1) Mobile/HomeAssistant, like Safari)
Traceback (most recent call last):
  File "/usr/local/lib/python3.13/site-packages/sqlalchemy/engine/base.py", line 1963, in _exec_single_context
    self.dialect.do_execute(
    ~~~~~~~~~~~~~~~~~~~~~~~^
        cursor, str_statement, effective_parameters, context
        ^^^^^^^^^^^^^^^^^^^^^^^^^^^^^^^^^^^^^^^^^^^^^^^^^^^^
    )
    ^
  File "/usr/local/lib/python3.13/site-packages/sqlalchemy/engine/default.py", line 943, in do_execute
    cursor.execute(statement, parameters)
    ~~~~~~~~~~~~~~^^^^^^^^^^^^^^^^^^^^^^^
sqlite3.OperationalError: no such table: statistics_meta

The above exception was the direct cause of the following exception:

Traceback (most recent call last):
  File "/usr/src/homeassistant/homeassistant/components/websocket_api/decorators.py", line 28, in _handle_async_response
    await func(hass, connection, msg)
  File "/usr/src/homeassistant/homeassistant/components/recorder/websocket_api.py", line 256, in ws_get_statistics_during_period
    await ws_handle_get_statistics_during_period(hass, connection, msg)
  File "/usr/src/homeassistant/homeassistant/components/recorder/websocket_api.py", line 223, in ws_handle_get_statistics_during_period
    await get_instance(hass).async_add_executor_job(
    ...<9 lines>...
    )
  File "/usr/local/lib/python3.13/concurrent/futures/thread.py", line 59, in run
    result = self.fn(*self.args, **self.kwargs)
  File "/usr/src/homeassistant/homeassistant/components/recorder/websocket_api.py", line 179, in _ws_get_statistics_during_period
    result = statistics_during_period(
        hass,
    ...<5 lines>...
        types,
    )
  File "/usr/src/homeassistant/homeassistant/components/recorder/statistics.py", line 1989, in statistics_during_period
    return _statistics_during_period_with_session(
        hass,
    ...<6 lines>...
        types,
    )
  File "/usr/src/homeassistant/homeassistant/components/recorder/statistics.py", line 1879, in _statistics_during_period_with_session
    metadata = get_instance(hass).statistics_meta_manager.get_many(
        session, statistic_ids=statistic_ids
    )
  File "/usr/src/homeassistant/homeassistant/components/recorder/table_managers/statistics_meta.py", line 282, in get_many
    return results | self._get_from_database(
                     ~~~~~~~~~~~~~~~~~~~~~~~^
        session, statistic_ids=missing_statistic_id
        ^^^^^^^^^^^^^^^^^^^^^^^^^^^^^^^^^^^^^^^^^^^
    )
    ^
  File "/usr/src/homeassistant/homeassistant/components/recorder/table_managers/statistics_meta.py", line 115, in _get_from_database
    for row in execute_stmt_lambda_element(
               ~~~~~~~~~~~~~~~~~~~~~~~~~~~^
        session,
        ^^^^^^^^
    ...<6 lines>...
        orm_rows=False,
        ^^^^^^^^^^^^^^^
    ):
    ^
  File "/usr/src/homeassistant/homeassistant/components/recorder/util.py", line 190, in execute_stmt_lambda_element
    executed = session.connection().execute(stmt)
  File "/usr/local/lib/python3.13/site-packages/sqlalchemy/engine/base.py", line 1415, in execute
    return meth(
        self,
        distilled_parameters,
        execution_options or NO_OPTIONS,
    )
  File "/usr/local/lib/python3.13/site-packages/sqlalchemy/sql/lambdas.py", line 594, in _execute_on_connection
    return connection._execute_clauseelement(
           ~~~~~~~~~~~~~~~~~~~~~~~~~~~~~~~~~^
        self, distilled_params, execution_options
        ^^^^^^^^^^^^^^^^^^^^^^^^^^^^^^^^^^^^^^^^^
    )
    ^
  File "/usr/local/lib/python3.13/site-packages/sqlalchemy/engine/base.py", line 1637, in _execute_clauseelement
    ret = self._execute_context(
        dialect,
    ...<8 lines>...
        cache_hit=cache_hit,
    )
  File "/usr/local/lib/python3.13/site-packages/sqlalchemy/engine/base.py", line 1842, in _execute_context
    return self._exec_single_context(
           ~~~~~~~~~~~~~~~~~~~~~~~~~^
        dialect, context, statement, parameters
        ^^^^^^^^^^^^^^^^^^^^^^^^^^^^^^^^^^^^^^^
    )
    ^
  File "/usr/local/lib/python3.13/site-packages/sqlalchemy/engine/base.py", line 1982, in _exec_single_context
    self._handle_dbapi_exception(
    ~~~~~~~~~~~~~~~~~~~~~~~~~~~~^
        e, str_statement, effective_parameters, cursor, context
        ^^^^^^^^^^^^^^^^^^^^^^^^^^^^^^^^^^^^^^^^^^^^^^^^^^^^^^^
    )
    ^
  File "/usr/local/lib/python3.13/site-packages/sqlalchemy/engine/base.py", line 2351, in _handle_dbapi_exception
    raise sqlalchemy_exception.with_traceback(exc_info[2]) from e
  File "/usr/local/lib/python3.13/site-packages/sqlalchemy/engine/base.py", line 1963, in _exec_single_context
    self.dialect.do_execute(
    ~~~~~~~~~~~~~~~~~~~~~~~^
        cursor, str_statement, effective_parameters, context
        ^^^^^^^^^^^^^^^^^^^^^^^^^^^^^^^^^^^^^^^^^^^^^^^^^^^^
    )
    ^
  File "/usr/local/lib/python3.13/site-packages/sqlalchemy/engine/default.py", line 943, in do_execute
    cursor.execute(statement, parameters)
    ~~~~~~~~~~~~~~^^^^^^^^^^^^^^^^^^^^^^^
sqlalchemy.exc.OperationalError: (sqlite3.OperationalError) no such table: statistics_meta
[SQL: SELECT statistics_meta.id, statistics_meta.statistic_id, statistics_meta.source, statistics_meta.unit_of_measurement, statistics_meta.has_sum, statistics_meta.name, statistics_meta.mean_type 
FROM statistics_meta 
WHERE statistics_meta.statistic_id IN (?)]
[parameters: ('sun.sun',)]
(Background on this error at: https://sqlalche.me/e/20/e3q8)
2025-10-11 11:44:54.668 ERROR (MainThread) [homeassistant.components.websocket_api.http.connection] [281471705842048] Error handling message: Unknown error (unknown_error) Blake Foster from 192.168.1.65 (Mozilla/5.0 (iPhone; CPU iPhone OS 18_7 like Mac OS X) AppleWebKit/605.1.15 (KHTML, like Gecko) Home Assistant/2025.9.3 (io.robbie.HomeAssistant; build:2025.1423; iOS 26.0.1) Mobile/HomeAssistant, like Safari)
Traceback (most recent call last):
  File "/usr/local/lib/python3.13/site-packages/sqlalchemy/engine/base.py", line 1963, in _exec_single_context
    self.dialect.do_execute(
    ~~~~~~~~~~~~~~~~~~~~~~~^
        cursor, str_statement, effective_parameters, context
        ^^^^^^^^^^^^^^^^^^^^^^^^^^^^^^^^^^^^^^^^^^^^^^^^^^^^
    )
    ^
  File "/usr/local/lib/python3.13/site-packages/sqlalchemy/engine/default.py", line 943, in do_execute
    cursor.execute(statement, parameters)
    ~~~~~~~~~~~~~~^^^^^^^^^^^^^^^^^^^^^^^
sqlite3.OperationalError: no such table: states

The above exception was the direct cause of the following exception:

Traceback (most recent call last):
  File "/usr/src/homeassistant/homeassistant/components/websocket_api/decorators.py", line 28, in _handle_async_response
    await func(hass, connection, msg)
  File "/usr/src/homeassistant/homeassistant/components/history/websocket_api.py", line 572, in ws_stream
    await _async_send_historical_states(
    ...<14 lines>...
    )
  File "/usr/src/homeassistant/homeassistant/components/history/websocket_api.py", line 287, in _async_send_historical_states
    last_time_ts, last_time_dt, payload = await instance.async_add_executor_job(
                                          ^^^^^^^^^^^^^^^^^^^^^^^^^^^^^^^^^^^^^^
    ...<11 lines>...
    )
    ^
  File "/usr/local/lib/python3.13/concurrent/futures/thread.py", line 59, in run
    result = self.fn(*self.args, **self.kwargs)
  File "/usr/src/homeassistant/homeassistant/components/history/websocket_api.py", line 233, in _generate_historical_response
    history.get_significant_states(
    ~~~~~~~~~~~~~~~~~~~~~~~~~~~~~~^
        hass,
        ^^^^^
    ...<8 lines>...
        True,
        ^^^^^
    ),
    ^
  File "/usr/src/homeassistant/homeassistant/components/recorder/history/__init__.py", line 104, in get_significant_states
    return _target(
        hass,
    ...<8 lines>...
        compressed_state_format,
    )
  File "/usr/src/homeassistant/homeassistant/components/recorder/history/modern.py", line 129, in get_significant_states
    return get_significant_states_with_session(
        hass,
    ...<9 lines>...
        compressed_state_format,
    )
  File "/usr/src/homeassistant/homeassistant/components/recorder/history/modern.py", line 293, in get_significant_states_with_session
    execute_stmt_lambda_element(session, stmt, None, end_time, orm_rows=False),
    ~~~~~~~~~~~~~~~~~~~~~~~~~~~^^^^^^^^^^^^^^^^^^^^^^^^^^^^^^^^^^^^^^^^^^^^^^^
  File "/usr/src/homeassistant/homeassistant/components/recorder/util.py", line 190, in execute_stmt_lambda_element
    executed = session.connection().execute(stmt)
  File "/usr/local/lib/python3.13/site-packages/sqlalchemy/engine/base.py", line 1415, in execute
    return meth(
        self,
        distilled_parameters,
        execution_options or NO_OPTIONS,
    )
  File "/usr/local/lib/python3.13/site-packages/sqlalchemy/sql/lambdas.py", line 594, in _execute_on_connection
    return connection._execute_clauseelement(
           ~~~~~~~~~~~~~~~~~~~~~~~~~~~~~~~~~^
        self, distilled_params, execution_options
        ^^^^^^^^^^^^^^^^^^^^^^^^^^^^^^^^^^^^^^^^^
    )
    ^
  File "/usr/local/lib/python3.13/site-packages/sqlalchemy/engine/base.py", line 1637, in _execute_clauseelement
    ret = self._execute_context(
        dialect,
    ...<8 lines>...
        cache_hit=cache_hit,
    )
  File "/usr/local/lib/python3.13/site-packages/sqlalchemy/engine/base.py", line 1842, in _execute_context
    return self._exec_single_context(
           ~~~~~~~~~~~~~~~~~~~~~~~~~^
        dialect, context, statement, parameters
        ^^^^^^^^^^^^^^^^^^^^^^^^^^^^^^^^^^^^^^^
    )
    ^
  File "/usr/local/lib/python3.13/site-packages/sqlalchemy/engine/base.py", line 1982, in _exec_single_context
    self._handle_dbapi_exception(
    ~~~~~~~~~~~~~~~~~~~~~~~~~~~~^
        e, str_statement, effective_parameters, cursor, context
        ^^^^^^^^^^^^^^^^^^^^^^^^^^^^^^^^^^^^^^^^^^^^^^^^^^^^^^^
    )
    ^
  File "/usr/local/lib/python3.13/site-packages/sqlalchemy/engine/base.py", line 2351, in _handle_dbapi_exception
    raise sqlalchemy_exception.with_traceback(exc_info[2]) from e
  File "/usr/local/lib/python3.13/site-packages/sqlalchemy/engine/base.py", line 1963, in _exec_single_context
    self.dialect.do_execute(
    ~~~~~~~~~~~~~~~~~~~~~~~^
        cursor, str_statement, effective_parameters, context
        ^^^^^^^^^^^^^^^^^^^^^^^^^^^^^^^^^^^^^^^^^^^^^^^^^^^^
    )
    ^
  File "/usr/local/lib/python3.13/site-packages/sqlalchemy/engine/default.py", line 943, in do_execute
    cursor.execute(statement, parameters)
    ~~~~~~~~~~~~~~^^^^^^^^^^^^^^^^^^^^^^^
sqlalchemy.exc.OperationalError: (sqlite3.OperationalError) no such table: states
[SQL: SELECT states.metadata_id, states.state, states.last_updated_ts 
FROM states 
WHERE (states.last_changed_ts = states.last_updated_ts OR states.last_changed_ts IS NULL) AND states.metadata_id IN (?) AND states.last_updated_ts > ? AND states.last_updated_ts < ? ORDER BY states.metadata_id, states.last_updated_ts]
[parameters: (45, 1760186486.138183, 1760201094.3874)]
(Background on this error at: https://sqlalche.me/e/20/e3q8)
2025-10-11 11:45:01.881 ERROR (MainThread) [frontend.js.modern.202509035] Uncaught error from WebKit 605.1.15 on iOS 18.7
TypeError: undefined is not an object (evaluating 'Object.getOwnPropertyNames(t)')
getOwnPropertyNames ([native code]::)
o (node_modules/deep-freeze/index.js:4:29)
_handleConfigChanged (src/panels/lovelace/editor/card-editor/hui-dialog-edit-card.ts:275:34)
this (src/lit-html.ts:2109:33)
dispatchEvent ([native code]::)
event (src/common/dom/fire_event.ts:75:21)
this._updateConfigElement (src/panels/lovelace/editor/hui-element-editor.ts:110:16)
2025-10-11 11:47:35.370 ERROR (DbWorker_3) [homeassistant.components.recorder.util] Error executing query: (sqlite3.OperationalError) no such table: statistics_meta
[SQL: SELECT statistics_meta.id, statistics_meta.statistic_id, statistics_meta.source, statistics_meta.unit_of_measurement, statistics_meta.has_sum, statistics_meta.name, statistics_meta.mean_type 
FROM statistics_meta 
WHERE statistics_meta.statistic_id IN (?)]
[parameters: ('sun.sun',)]
(Background on this error at: https://sqlalche.me/e/20/e3q8)
2025-10-11 11:47:35.421 ERROR (DbWorker_2) [homeassistant.components.recorder.util] Error executing query: (sqlite3.OperationalError) no such table: states
[SQL: SELECT states.metadata_id, states.state, states.last_updated_ts 
FROM states 
WHERE (states.last_changed_ts = states.last_updated_ts OR states.last_changed_ts IS NULL) AND states.metadata_id IN (?) AND states.last_updated_ts > ? AND states.last_updated_ts < ? ORDER BY states.metadata_id, states.last_updated_ts]
[parameters: (45, 1760186486.138183, 1760201255.352521)]
(Background on this error at: https://sqlalche.me/e/20/e3q8)
2025-10-11 11:47:35.472 ERROR (DbWorker_3) [homeassistant.components.recorder.util] Error executing query: (sqlite3.OperationalError) no such table: statistics_meta
[SQL: SELECT statistics_meta.id, statistics_meta.statistic_id, statistics_meta.source, statistics_meta.unit_of_measurement, statistics_meta.has_sum, statistics_meta.name, statistics_meta.mean_type 
FROM statistics_meta 
WHERE statistics_meta.statistic_id IN (?)]
[parameters: ('sun.sun',)]
(Background on this error at: https://sqlalche.me/e/20/e3q8)
2025-10-11 11:47:35.524 ERROR (DbWorker_2) [homeassistant.components.recorder.util] Error executing query: (sqlite3.OperationalError) no such table: states
[SQL: SELECT states.metadata_id, states.state, states.last_updated_ts 
FROM states 
WHERE (states.last_changed_ts = states.last_updated_ts OR states.last_changed_ts IS NULL) AND states.metadata_id IN (?) AND states.last_updated_ts > ? AND states.last_updated_ts < ? ORDER BY states.metadata_id, states.last_updated_ts]
[parameters: (45, 1760186486.138183, 1760201255.352521)]
(Background on this error at: https://sqlalche.me/e/20/e3q8)
2025-10-11 11:47:35.574 ERROR (DbWorker_3) [homeassistant.components.recorder.util] Error executing query: (sqlite3.OperationalError) no such table: statistics_meta
[SQL: SELECT statistics_meta.id, statistics_meta.statistic_id, statistics_meta.source, statistics_meta.unit_of_measurement, statistics_meta.has_sum, statistics_meta.name, statistics_meta.mean_type 
FROM statistics_meta 
WHERE statistics_meta.statistic_id IN (?)]
[parameters: ('sun.sun',)]
(Background on this error at: https://sqlalche.me/e/20/e3q8)
2025-10-11 11:47:35.574 ERROR (DbWorker_3) [homeassistant.helpers.recorder] Error executing query
Traceback (most recent call last):
  File "/usr/local/lib/python3.13/site-packages/sqlalchemy/engine/base.py", line 1963, in _exec_single_context
    self.dialect.do_execute(
    ~~~~~~~~~~~~~~~~~~~~~~~^
        cursor, str_statement, effective_parameters, context
        ^^^^^^^^^^^^^^^^^^^^^^^^^^^^^^^^^^^^^^^^^^^^^^^^^^^^
    )
    ^
  File "/usr/local/lib/python3.13/site-packages/sqlalchemy/engine/default.py", line 943, in do_execute
    cursor.execute(statement, parameters)
    ~~~~~~~~~~~~~~^^^^^^^^^^^^^^^^^^^^^^^
sqlite3.OperationalError: no such table: statistics_meta

The above exception was the direct cause of the following exception:

Traceback (most recent call last):
  File "/usr/src/homeassistant/homeassistant/helpers/recorder.py", line 95, in session_scope
    yield session
  File "/usr/src/homeassistant/homeassistant/components/recorder/statistics.py", line 1989, in statistics_during_period
    return _statistics_during_period_with_session(
        hass,
    ...<6 lines>...
        types,
    )
  File "/usr/src/homeassistant/homeassistant/components/recorder/statistics.py", line 1879, in _statistics_during_period_with_session
    metadata = get_instance(hass).statistics_meta_manager.get_many(
        session, statistic_ids=statistic_ids
    )
  File "/usr/src/homeassistant/homeassistant/components/recorder/table_managers/statistics_meta.py", line 282, in get_many
    return results | self._get_from_database(
                     ~~~~~~~~~~~~~~~~~~~~~~~^
        session, statistic_ids=missing_statistic_id
        ^^^^^^^^^^^^^^^^^^^^^^^^^^^^^^^^^^^^^^^^^^^
    )
    ^
  File "/usr/src/homeassistant/homeassistant/components/recorder/table_managers/statistics_meta.py", line 115, in _get_from_database
    for row in execute_stmt_lambda_element(
               ~~~~~~~~~~~~~~~~~~~~~~~~~~~^
        session,
        ^^^^^^^^
    ...<6 lines>...
        orm_rows=False,
        ^^^^^^^^^^^^^^^
    ):
    ^
  File "/usr/src/homeassistant/homeassistant/components/recorder/util.py", line 190, in execute_stmt_lambda_element
    executed = session.connection().execute(stmt)
  File "/usr/local/lib/python3.13/site-packages/sqlalchemy/engine/base.py", line 1415, in execute
    return meth(
        self,
        distilled_parameters,
        execution_options or NO_OPTIONS,
    )
  File "/usr/local/lib/python3.13/site-packages/sqlalchemy/sql/lambdas.py", line 594, in _execute_on_connection
    return connection._execute_clauseelement(
           ~~~~~~~~~~~~~~~~~~~~~~~~~~~~~~~~~^
        self, distilled_params, execution_options
        ^^^^^^^^^^^^^^^^^^^^^^^^^^^^^^^^^^^^^^^^^
    )
    ^
  File "/usr/local/lib/python3.13/site-packages/sqlalchemy/engine/base.py", line 1637, in _execute_clauseelement
    ret = self._execute_context(
        dialect,
    ...<8 lines>...
        cache_hit=cache_hit,
    )
  File "/usr/local/lib/python3.13/site-packages/sqlalchemy/engine/base.py", line 1842, in _execute_context
    return self._exec_single_context(
           ~~~~~~~~~~~~~~~~~~~~~~~~~^
        dialect, context, statement, parameters
        ^^^^^^^^^^^^^^^^^^^^^^^^^^^^^^^^^^^^^^^
    )
    ^
  File "/usr/local/lib/python3.13/site-packages/sqlalchemy/engine/base.py", line 1982, in _exec_single_context
    self._handle_dbapi_exception(
    ~~~~~~~~~~~~~~~~~~~~~~~~~~~~^
        e, str_statement, effective_parameters, cursor, context
        ^^^^^^^^^^^^^^^^^^^^^^^^^^^^^^^^^^^^^^^^^^^^^^^^^^^^^^^
    )
    ^
  File "/usr/local/lib/python3.13/site-packages/sqlalchemy/engine/base.py", line 2351, in _handle_dbapi_exception
    raise sqlalchemy_exception.with_traceback(exc_info[2]) from e
  File "/usr/local/lib/python3.13/site-packages/sqlalchemy/engine/base.py", line 1963, in _exec_single_context
    self.dialect.do_execute(
    ~~~~~~~~~~~~~~~~~~~~~~~^
        cursor, str_statement, effective_parameters, context
        ^^^^^^^^^^^^^^^^^^^^^^^^^^^^^^^^^^^^^^^^^^^^^^^^^^^^
    )
    ^
  File "/usr/local/lib/python3.13/site-packages/sqlalchemy/engine/default.py", line 943, in do_execute
    cursor.execute(statement, parameters)
    ~~~~~~~~~~~~~~^^^^^^^^^^^^^^^^^^^^^^^
sqlalchemy.exc.OperationalError: (sqlite3.OperationalError) no such table: statistics_meta
[SQL: SELECT statistics_meta.id, statistics_meta.statistic_id, statistics_meta.source, statistics_meta.unit_of_measurement, statistics_meta.has_sum, statistics_meta.name, statistics_meta.mean_type 
FROM statistics_meta 
WHERE statistics_meta.statistic_id IN (?)]
[parameters: ('sun.sun',)]
(Background on this error at: https://sqlalche.me/e/20/e3q8)
2025-10-11 11:47:35.593 ERROR (MainThread) [homeassistant.components.websocket_api.http.connection] [281471705842048] Error handling message: Unknown error (unknown_error) Blake Foster from 192.168.1.65 (Mozilla/5.0 (iPhone; CPU iPhone OS 18_7 like Mac OS X) AppleWebKit/605.1.15 (KHTML, like Gecko) Home Assistant/2025.9.3 (io.robbie.HomeAssistant; build:2025.1423; iOS 26.0.1) Mobile/HomeAssistant, like Safari)
Traceback (most recent call last):
  File "/usr/local/lib/python3.13/site-packages/sqlalchemy/engine/base.py", line 1963, in _exec_single_context
    self.dialect.do_execute(
    ~~~~~~~~~~~~~~~~~~~~~~~^
        cursor, str_statement, effective_parameters, context
        ^^^^^^^^^^^^^^^^^^^^^^^^^^^^^^^^^^^^^^^^^^^^^^^^^^^^
    )
    ^
  File "/usr/local/lib/python3.13/site-packages/sqlalchemy/engine/default.py", line 943, in do_execute
    cursor.execute(statement, parameters)
    ~~~~~~~~~~~~~~^^^^^^^^^^^^^^^^^^^^^^^
sqlite3.OperationalError: no such table: statistics_meta

The above exception was the direct cause of the following exception:

Traceback (most recent call last):
  File "/usr/src/homeassistant/homeassistant/components/websocket_api/decorators.py", line 28, in _handle_async_response
    await func(hass, connection, msg)
  File "/usr/src/homeassistant/homeassistant/components/recorder/websocket_api.py", line 256, in ws_get_statistics_during_period
    await ws_handle_get_statistics_during_period(hass, connection, msg)
  File "/usr/src/homeassistant/homeassistant/components/recorder/websocket_api.py", line 223, in ws_handle_get_statistics_during_period
    await get_instance(hass).async_add_executor_job(
    ...<9 lines>...
    )
  File "/usr/local/lib/python3.13/concurrent/futures/thread.py", line 59, in run
    result = self.fn(*self.args, **self.kwargs)
  File "/usr/src/homeassistant/homeassistant/components/recorder/websocket_api.py", line 179, in _ws_get_statistics_during_period
    result = statistics_during_period(
        hass,
    ...<5 lines>...
        types,
    )
  File "/usr/src/homeassistant/homeassistant/components/recorder/statistics.py", line 1989, in statistics_during_period
    return _statistics_during_period_with_session(
        hass,
    ...<6 lines>...
        types,
    )
  File "/usr/src/homeassistant/homeassistant/components/recorder/statistics.py", line 1879, in _statistics_during_period_with_session
    metadata = get_instance(hass).statistics_meta_manager.get_many(
        session, statistic_ids=statistic_ids
    )
  File "/usr/src/homeassistant/homeassistant/components/recorder/table_managers/statistics_meta.py", line 282, in get_many
    return results | self._get_from_database(
                     ~~~~~~~~~~~~~~~~~~~~~~~^
        session, statistic_ids=missing_statistic_id
        ^^^^^^^^^^^^^^^^^^^^^^^^^^^^^^^^^^^^^^^^^^^
    )
    ^
  File "/usr/src/homeassistant/homeassistant/components/recorder/table_managers/statistics_meta.py", line 115, in _get_from_database
    for row in execute_stmt_lambda_element(
               ~~~~~~~~~~~~~~~~~~~~~~~~~~~^
        session,
        ^^^^^^^^
    ...<6 lines>...
        orm_rows=False,
        ^^^^^^^^^^^^^^^
    ):
    ^
  File "/usr/src/homeassistant/homeassistant/components/recorder/util.py", line 190, in execute_stmt_lambda_element
    executed = session.connection().execute(stmt)
  File "/usr/local/lib/python3.13/site-packages/sqlalchemy/engine/base.py", line 1415, in execute
    return meth(
        self,
        distilled_parameters,
        execution_options or NO_OPTIONS,
    )
  File "/usr/local/lib/python3.13/site-packages/sqlalchemy/sql/lambdas.py", line 594, in _execute_on_connection
    return connection._execute_clauseelement(
           ~~~~~~~~~~~~~~~~~~~~~~~~~~~~~~~~~^
        self, distilled_params, execution_options
        ^^^^^^^^^^^^^^^^^^^^^^^^^^^^^^^^^^^^^^^^^
    )
    ^
  File "/usr/local/lib/python3.13/site-packages/sqlalchemy/engine/base.py", line 1637, in _execute_clauseelement
    ret = self._execute_context(
        dialect,
    ...<8 lines>...
        cache_hit=cache_hit,
    )
  File "/usr/local/lib/python3.13/site-packages/sqlalchemy/engine/base.py", line 1842, in _execute_context
    return self._exec_single_context(
           ~~~~~~~~~~~~~~~~~~~~~~~~~^
        dialect, context, statement, parameters
        ^^^^^^^^^^^^^^^^^^^^^^^^^^^^^^^^^^^^^^^
    )
    ^
  File "/usr/local/lib/python3.13/site-packages/sqlalchemy/engine/base.py", line 1982, in _exec_single_context
    self._handle_dbapi_exception(
    ~~~~~~~~~~~~~~~~~~~~~~~~~~~~^
        e, str_statement, effective_parameters, cursor, context
        ^^^^^^^^^^^^^^^^^^^^^^^^^^^^^^^^^^^^^^^^^^^^^^^^^^^^^^^
    )
    ^
  File "/usr/local/lib/python3.13/site-packages/sqlalchemy/engine/base.py", line 2351, in _handle_dbapi_exception
    raise sqlalchemy_exception.with_traceback(exc_info[2]) from e
  File "/usr/local/lib/python3.13/site-packages/sqlalchemy/engine/base.py", line 1963, in _exec_single_context
    self.dialect.do_execute(
    ~~~~~~~~~~~~~~~~~~~~~~~^
        cursor, str_statement, effective_parameters, context
        ^^^^^^^^^^^^^^^^^^^^^^^^^^^^^^^^^^^^^^^^^^^^^^^^^^^^
    )
    ^
  File "/usr/local/lib/python3.13/site-packages/sqlalchemy/engine/default.py", line 943, in do_execute
    cursor.execute(statement, parameters)
    ~~~~~~~~~~~~~~^^^^^^^^^^^^^^^^^^^^^^^
sqlalchemy.exc.OperationalError: (sqlite3.OperationalError) no such table: statistics_meta
[SQL: SELECT statistics_meta.id, statistics_meta.statistic_id, statistics_meta.source, statistics_meta.unit_of_measurement, statistics_meta.has_sum, statistics_meta.name, statistics_meta.mean_type 
FROM statistics_meta 
WHERE statistics_meta.statistic_id IN (?)]
[parameters: ('sun.sun',)]
(Background on this error at: https://sqlalche.me/e/20/e3q8)
2025-10-11 11:47:35.626 ERROR (DbWorker_2) [homeassistant.components.recorder.util] Error executing query: (sqlite3.OperationalError) no such table: states
[SQL: SELECT states.metadata_id, states.state, states.last_updated_ts 
FROM states 
WHERE (states.last_changed_ts = states.last_updated_ts OR states.last_changed_ts IS NULL) AND states.metadata_id IN (?) AND states.last_updated_ts > ? AND states.last_updated_ts < ? ORDER BY states.metadata_id, states.last_updated_ts]
[parameters: (45, 1760186486.138183, 1760201255.352521)]
(Background on this error at: https://sqlalche.me/e/20/e3q8)
2025-10-11 11:47:35.627 ERROR (DbWorker_2) [homeassistant.helpers.recorder] Error executing query
Traceback (most recent call last):
  File "/usr/local/lib/python3.13/site-packages/sqlalchemy/engine/base.py", line 1963, in _exec_single_context
    self.dialect.do_execute(
    ~~~~~~~~~~~~~~~~~~~~~~~^
        cursor, str_statement, effective_parameters, context
        ^^^^^^^^^^^^^^^^^^^^^^^^^^^^^^^^^^^^^^^^^^^^^^^^^^^^
    )
    ^
  File "/usr/local/lib/python3.13/site-packages/sqlalchemy/engine/default.py", line 943, in do_execute
    cursor.execute(statement, parameters)
    ~~~~~~~~~~~~~~^^^^^^^^^^^^^^^^^^^^^^^
sqlite3.OperationalError: no such table: states

The above exception was the direct cause of the following exception:

Traceback (most recent call last):
  File "/usr/src/homeassistant/homeassistant/helpers/recorder.py", line 95, in session_scope
    yield session
  File "/usr/src/homeassistant/homeassistant/components/recorder/history/modern.py", line 129, in get_significant_states
    return get_significant_states_with_session(
        hass,
    ...<9 lines>...
        compressed_state_format,
    )
  File "/usr/src/homeassistant/homeassistant/components/recorder/history/modern.py", line 293, in get_significant_states_with_session
    execute_stmt_lambda_element(session, stmt, None, end_time, orm_rows=False),
    ~~~~~~~~~~~~~~~~~~~~~~~~~~~^^^^^^^^^^^^^^^^^^^^^^^^^^^^^^^^^^^^^^^^^^^^^^^
  File "/usr/src/homeassistant/homeassistant/components/recorder/util.py", line 190, in execute_stmt_lambda_element
    executed = session.connection().execute(stmt)
  File "/usr/local/lib/python3.13/site-packages/sqlalchemy/engine/base.py", line 1415, in execute
    return meth(
        self,
        distilled_parameters,
        execution_options or NO_OPTIONS,
    )
  File "/usr/local/lib/python3.13/site-packages/sqlalchemy/sql/lambdas.py", line 594, in _execute_on_connection
    return connection._execute_clauseelement(
           ~~~~~~~~~~~~~~~~~~~~~~~~~~~~~~~~~^
        self, distilled_params, execution_options
        ^^^^^^^^^^^^^^^^^^^^^^^^^^^^^^^^^^^^^^^^^
    )
    ^
  File "/usr/local/lib/python3.13/site-packages/sqlalchemy/engine/base.py", line 1637, in _execute_clauseelement
    ret = self._execute_context(
        dialect,
    ...<8 lines>...
        cache_hit=cache_hit,
    )
  File "/usr/local/lib/python3.13/site-packages/sqlalchemy/engine/base.py", line 1842, in _execute_context
    return self._exec_single_context(
           ~~~~~~~~~~~~~~~~~~~~~~~~~^
        dialect, context, statement, parameters
        ^^^^^^^^^^^^^^^^^^^^^^^^^^^^^^^^^^^^^^^
    )
    ^
  File "/usr/local/lib/python3.13/site-packages/sqlalchemy/engine/base.py", line 1982, in _exec_single_context
    self._handle_dbapi_exception(
    ~~~~~~~~~~~~~~~~~~~~~~~~~~~~^
        e, str_statement, effective_parameters, cursor, context
        ^^^^^^^^^^^^^^^^^^^^^^^^^^^^^^^^^^^^^^^^^^^^^^^^^^^^^^^
    )
    ^
  File "/usr/local/lib/python3.13/site-packages/sqlalchemy/engine/base.py", line 2351, in _handle_dbapi_exception
    raise sqlalchemy_exception.with_traceback(exc_info[2]) from e
  File "/usr/local/lib/python3.13/site-packages/sqlalchemy/engine/base.py", line 1963, in _exec_single_context
    self.dialect.do_execute(
    ~~~~~~~~~~~~~~~~~~~~~~~^
        cursor, str_statement, effective_parameters, context
        ^^^^^^^^^^^^^^^^^^^^^^^^^^^^^^^^^^^^^^^^^^^^^^^^^^^^
    )
    ^
  File "/usr/local/lib/python3.13/site-packages/sqlalchemy/engine/default.py", line 943, in do_execute
    cursor.execute(statement, parameters)
    ~~~~~~~~~~~~~~^^^^^^^^^^^^^^^^^^^^^^^
sqlalchemy.exc.OperationalError: (sqlite3.OperationalError) no such table: states
[SQL: SELECT states.metadata_id, states.state, states.last_updated_ts 
FROM states 
WHERE (states.last_changed_ts = states.last_updated_ts OR states.last_changed_ts IS NULL) AND states.metadata_id IN (?) AND states.last_updated_ts > ? AND states.last_updated_ts < ? ORDER BY states.metadata_id, states.last_updated_ts]
[parameters: (45, 1760186486.138183, 1760201255.352521)]
(Background on this error at: https://sqlalche.me/e/20/e3q8)
2025-10-11 11:47:35.651 ERROR (MainThread) [homeassistant.components.websocket_api.http.connection] [281471705842048] Error handling message: Unknown error (unknown_error) Blake Foster from 192.168.1.65 (Mozilla/5.0 (iPhone; CPU iPhone OS 18_7 like Mac OS X) AppleWebKit/605.1.15 (KHTML, like Gecko) Home Assistant/2025.9.3 (io.robbie.HomeAssistant; build:2025.1423; iOS 26.0.1) Mobile/HomeAssistant, like Safari)
Traceback (most recent call last):
  File "/usr/local/lib/python3.13/site-packages/sqlalchemy/engine/base.py", line 1963, in _exec_single_context
    self.dialect.do_execute(
    ~~~~~~~~~~~~~~~~~~~~~~~^
        cursor, str_statement, effective_parameters, context
        ^^^^^^^^^^^^^^^^^^^^^^^^^^^^^^^^^^^^^^^^^^^^^^^^^^^^
    )
    ^
  File "/usr/local/lib/python3.13/site-packages/sqlalchemy/engine/default.py", line 943, in do_execute
    cursor.execute(statement, parameters)
    ~~~~~~~~~~~~~~^^^^^^^^^^^^^^^^^^^^^^^
sqlite3.OperationalError: no such table: states

The above exception was the direct cause of the following exception:

Traceback (most recent call last):
  File "/usr/src/homeassistant/homeassistant/components/websocket_api/decorators.py", line 28, in _handle_async_response
    await func(hass, connection, msg)
  File "/usr/src/homeassistant/homeassistant/components/history/websocket_api.py", line 572, in ws_stream
    await _async_send_historical_states(
    ...<14 lines>...
    )
  File "/usr/src/homeassistant/homeassistant/components/history/websocket_api.py", line 287, in _async_send_historical_states
    last_time_ts, last_time_dt, payload = await instance.async_add_executor_job(
                                          ^^^^^^^^^^^^^^^^^^^^^^^^^^^^^^^^^^^^^^
    ...<11 lines>...
    )
    ^
  File "/usr/local/lib/python3.13/concurrent/futures/thread.py", line 59, in run
    result = self.fn(*self.args, **self.kwargs)
  File "/usr/src/homeassistant/homeassistant/components/history/websocket_api.py", line 233, in _generate_historical_response
    history.get_significant_states(
    ~~~~~~~~~~~~~~~~~~~~~~~~~~~~~~^
        hass,
        ^^^^^
    ...<8 lines>...
        True,
        ^^^^^
    ),
    ^
  File "/usr/src/homeassistant/homeassistant/components/recorder/history/__init__.py", line 104, in get_significant_states
    return _target(
        hass,
    ...<8 lines>...
        compressed_state_format,
    )
  File "/usr/src/homeassistant/homeassistant/components/recorder/history/modern.py", line 129, in get_significant_states
    return get_significant_states_with_session(
        hass,
    ...<9 lines>...
        compressed_state_format,
    )
  File "/usr/src/homeassistant/homeassistant/components/recorder/history/modern.py", line 293, in get_significant_states_with_session
    execute_stmt_lambda_element(session, stmt, None, end_time, orm_rows=False),
    ~~~~~~~~~~~~~~~~~~~~~~~~~~~^^^^^^^^^^^^^^^^^^^^^^^^^^^^^^^^^^^^^^^^^^^^^^^
  File "/usr/src/homeassistant/homeassistant/components/recorder/util.py", line 190, in execute_stmt_lambda_element
    executed = session.connection().execute(stmt)
  File "/usr/local/lib/python3.13/site-packages/sqlalchemy/engine/base.py", line 1415, in execute
    return meth(
        self,
        distilled_parameters,
        execution_options or NO_OPTIONS,
    )
  File "/usr/local/lib/python3.13/site-packages/sqlalchemy/sql/lambdas.py", line 594, in _execute_on_connection
    return connection._execute_clauseelement(
           ~~~~~~~~~~~~~~~~~~~~~~~~~~~~~~~~~^
        self, distilled_params, execution_options
        ^^^^^^^^^^^^^^^^^^^^^^^^^^^^^^^^^^^^^^^^^
    )
    ^
  File "/usr/local/lib/python3.13/site-packages/sqlalchemy/engine/base.py", line 1637, in _execute_clauseelement
    ret = self._execute_context(
        dialect,
    ...<8 lines>...
        cache_hit=cache_hit,
    )
  File "/usr/local/lib/python3.13/site-packages/sqlalchemy/engine/base.py", line 1842, in _execute_context
    return self._exec_single_context(
           ~~~~~~~~~~~~~~~~~~~~~~~~~^
        dialect, context, statement, parameters
        ^^^^^^^^^^^^^^^^^^^^^^^^^^^^^^^^^^^^^^^
    )
    ^
  File "/usr/local/lib/python3.13/site-packages/sqlalchemy/engine/base.py", line 1982, in _exec_single_context
    self._handle_dbapi_exception(
    ~~~~~~~~~~~~~~~~~~~~~~~~~~~~^
        e, str_statement, effective_parameters, cursor, context
        ^^^^^^^^^^^^^^^^^^^^^^^^^^^^^^^^^^^^^^^^^^^^^^^^^^^^^^^
    )
    ^
  File "/usr/local/lib/python3.13/site-packages/sqlalchemy/engine/base.py", line 2351, in _handle_dbapi_exception
    raise sqlalchemy_exception.with_traceback(exc_info[2]) from e
  File "/usr/local/lib/python3.13/site-packages/sqlalchemy/engine/base.py", line 1963, in _exec_single_context
    self.dialect.do_execute(
    ~~~~~~~~~~~~~~~~~~~~~~~^
        cursor, str_statement, effective_parameters, context
        ^^^^^^^^^^^^^^^^^^^^^^^^^^^^^^^^^^^^^^^^^^^^^^^^^^^^
    )
    ^
  File "/usr/local/lib/python3.13/site-packages/sqlalchemy/engine/default.py", line 943, in do_execute
    cursor.execute(statement, parameters)
    ~~~~~~~~~~~~~~^^^^^^^^^^^^^^^^^^^^^^^
sqlalchemy.exc.OperationalError: (sqlite3.OperationalError) no such table: states
[SQL: SELECT states.metadata_id, states.state, states.last_updated_ts 
FROM states 
WHERE (states.last_changed_ts = states.last_updated_ts OR states.last_changed_ts IS NULL) AND states.metadata_id IN (?) AND states.last_updated_ts > ? AND states.last_updated_ts < ? ORDER BY states.metadata_id, states.last_updated_ts]
[parameters: (45, 1760186486.138183, 1760201255.352521)]
(Background on this error at: https://sqlalche.me/e/20/e3q8)
2025-10-11 11:47:42.526 ERROR (MainThread) [frontend.js.modern.202509035] Uncaught error from WebKit 605.1.15 on iOS 18.7
TypeError: undefined is not an object (evaluating 'Object.getOwnPropertyNames(t)')
getOwnPropertyNames ([native code]::)
o (node_modules/deep-freeze/index.js:4:29)
_handleConfigChanged (src/panels/lovelace/editor/card-editor/hui-dialog-edit-card.ts:275:34)
this (src/lit-html.ts:2109:33)
dispatchEvent ([native code]::)
event (src/common/dom/fire_event.ts:75:21)
this._updateConfigElement (src/panels/lovelace/editor/hui-element-editor.ts:110:16)
2025-10-11 11:50:10.253 INFO (MainThread) [homeassistant.components.automation.bedroom_ceiling_fan_3_all_off] Bedroom Ceiling Fan (3)  -> All Off: Running automation actions
2025-10-11 11:50:10.255 INFO (MainThread) [homeassistant.components.automation.bedroom_ceiling_fan_3_all_off] Bedroom Ceiling Fan (3)  -> All Off: Choose at step 1: default: Running automation actions
2025-10-11 11:50:10.256 INFO (MainThread) [homeassistant.components.automation.bedroom_ceiling_fan_3_all_off] Bedroom Ceiling Fan (3)  -> All Off: Choose at step 1: default: Choose at step 1: choice 1: Running automation actions
2025-10-11 11:50:10.256 INFO (MainThread) [homeassistant.components.automation.bedroom_ceiling_fan_3_all_off] Bedroom Ceiling Fan (3)  -> All Off: Choose at step 1: default: Choose at step 1: choice 1: Executing step call service
2025-10-11 11:50:10.261 INFO (MainThread) [homeassistant.components.automation.bedroom_ceiling_fan_3_all_off] Bedroom Ceiling Fan (3)  -> All Off: Choose at step 1: default: Choose at step 1: choice 1: Executing step call service
2025-10-11 11:50:10.265 INFO (MainThread) [homeassistant.components.automation.bedroom_ceiling_fan_3_all_off] Bedroom Ceiling Fan (3)  -> All Off: Choose at step 1: default: Executing step call service
2025-10-11 11:50:25.002 INFO (MainThread) [homeassistant.components.automation.bedroom_ceiling_lights_3_set_my_room] Bedroom Ceiling Lights (3) -> Set My Room: Running automation actions
2025-10-11 11:50:25.004 INFO (MainThread) [homeassistant.components.automation.bedroom_ceiling_lights_3_set_my_room] Bedroom Ceiling Lights (3) -> Set My Room: Choose at step 1: choice 1: Running automation actions
2025-10-11 11:50:25.004 INFO (MainThread) [homeassistant.components.automation.bedroom_ceiling_lights_3_set_my_room] Bedroom Ceiling Lights (3) -> Set My Room: Choose at step 1: choice 1: Executing step call service
2025-10-11 11:50:25.011 INFO (MainThread) [homeassistant.components.automation.bedroom_ceiling_fan_3_all_off] Bedroom Ceiling Fan (3)  -> All Off: Running automation actions
2025-10-11 11:50:25.013 INFO (MainThread) [homeassistant.components.automation.bedroom_ceiling_fan_3_all_off] Bedroom Ceiling Fan (3)  -> All Off: Choose at step 1: choice 1: Running automation actions
2025-10-11 11:50:25.013 INFO (MainThread) [homeassistant.components.automation.bedroom_ceiling_fan_3_all_off] Bedroom Ceiling Fan (3)  -> All Off: Choose at step 1: choice 1: Executing step call service
2025-10-11 11:53:05.545 INFO (MainThread) [homeassistant.components.automation.bedroom_ceiling_fan_3_all_off] Bedroom Ceiling Fan (3)  -> All Off: Running automation actions
2025-10-11 11:53:05.546 INFO (MainThread) [homeassistant.components.automation.bedroom_ceiling_fan_3_all_off] Bedroom Ceiling Fan (3)  -> All Off: Choose at step 1: default: Running automation actions
2025-10-11 11:53:05.547 INFO (MainThread) [homeassistant.components.automation.bedroom_ceiling_fan_3_all_off] Bedroom Ceiling Fan (3)  -> All Off: Choose at step 1: default: Choose at step 1: choice 1: Running automation actions
2025-10-11 11:53:05.548 INFO (MainThread) [homeassistant.components.automation.bedroom_ceiling_fan_3_all_off] Bedroom Ceiling Fan (3)  -> All Off: Choose at step 1: default: Choose at step 1: choice 1: Executing step call service
2025-10-11 11:53:05.553 INFO (MainThread) [homeassistant.components.automation.bedroom_ceiling_fan_3_all_off] Bedroom Ceiling Fan (3)  -> All Off: Choose at step 1: default: Choose at step 1: choice 1: Executing step call service
2025-10-11 11:53:05.555 INFO (MainThread) [homeassistant.components.automation.bedroom_ceiling_fan_3_all_off] Bedroom Ceiling Fan (3)  -> All Off: Choose at step 1: default: Executing step call service
2025-10-11 11:53:08.454 INFO (MainThread) [homeassistant.components.automation.bedroom_ceiling_fan_3_all_off] Bedroom Ceiling Fan (3)  -> All Off: Running automation actions
2025-10-11 11:53:08.455 INFO (MainThread) [homeassistant.components.automation.bedroom_ceiling_fan_3_all_off] Bedroom Ceiling Fan (3)  -> All Off: Choose at step 1: default: Running automation actions
2025-10-11 11:53:08.457 INFO (MainThread) [homeassistant.components.automation.bedroom_ceiling_fan_3_all_off] Bedroom Ceiling Fan (3)  -> All Off: Choose at step 1: default: Executing step call service
2025-10-11 11:53:20.003 INFO (MainThread) [homeassistant.components.automation.bedroom_ceiling_lights_3_set_my_room] Bedroom Ceiling Lights (3) -> Set My Room: Running automation actions
2025-10-11 11:53:20.005 INFO (MainThread) [homeassistant.components.automation.bedroom_ceiling_lights_3_set_my_room] Bedroom Ceiling Lights (3) -> Set My Room: Choose at step 1: choice 1: Running automation actions
2025-10-11 11:53:20.005 INFO (MainThread) [homeassistant.components.automation.bedroom_ceiling_lights_3_set_my_room] Bedroom Ceiling Lights (3) -> Set My Room: Choose at step 1: choice 1: Executing step call service
2025-10-11 11:53:20.013 INFO (MainThread) [homeassistant.components.automation.bedroom_ceiling_fan_3_all_off] Bedroom Ceiling Fan (3)  -> All Off: Running automation actions
2025-10-11 11:53:20.014 INFO (MainThread) [homeassistant.components.automation.bedroom_ceiling_fan_3_all_off] Bedroom Ceiling Fan (3)  -> All Off: Choose at step 1: choice 1: Running automation actions
2025-10-11 11:53:20.014 INFO (MainThread) [homeassistant.components.automation.bedroom_ceiling_fan_3_all_off] Bedroom Ceiling Fan (3)  -> All Off: Choose at step 1: choice 1: Executing step call service
2025-10-11 11:57:28.631 INFO (MainThread) [homeassistant.components.script.create_push_ha_info_to_github] Create & Push HA Info to Github: Running script sequence
2025-10-11 11:57:28.631 INFO (MainThread) [homeassistant.components.script.create_push_ha_info_to_github] Create & Push HA Info to Github: Executing step call service
2025-10-11 11:57:28.711 INFO (MainThread) [homeassistant.components.script.create_push_ha_info_to_github] Create & Push HA Info to Github: Executing step call service
2025-10-11 11:57:28.746 INFO (MainThread) [homeassistant.components.script.create_push_ha_info_to_github] Create & Push HA Info to Github: Executing step call service
